<?xml version="1.0"?>
<robot xmlns:xacro="http://www.ros.org/wiki/xacro">

<!--Left Wheel-->
<link name="left_wheel">
    <visual>
        <origin xyz="0 0 0" rpy="0 0 0"/>
        <geometry>
            <cylinder radius="0.05" length="0.04"/>
        </geometry>
        <material name="blue"/>
    </visual>

    <collision>
        <origin xyz="0 0 0" rpy="0 0 0"/>
        <geometry>
            <cylinder radius="0.05" length="0.04"/>
        </geometry>
    </collision>

    <xacro:inertial_cylinder mass="0.1" radius="0.05" length="0.04">
        <origin xyz="0 0 0" rpy="0 0 0"/>
    </xacro:inertial_cylinder>

</link>

<joint name="left_wheel_joint" type="continuous">
    <parent link="base_link"/>
    <child link="left_wheel"/>
    <origin xyz="0 0.175 0.0" rpy="-${pi/2} 0 0"/>
    <axis xyz="0 0 1"/>
</joint>

<!--Right Wheel-->
<link name="right_wheel">
    <visual>
        <origin xyz="0 0 0" rpy="0 0 0"/>
        <geometry>
            <cylinder radius="0.05" length="0.04"/>
        </geometry>
        <material name="blue"/>
    </visual>

    <collision>
        <origin xyz="0 0 0" rpy="0 0 0"/>
        <geometry>
            <cylinder radius="0.05" length="0.04"/>
        </geometry>
    </collision>

    <xacro:inertial_cylinder mass="0.1" radius="0.05" length="0.04">
        <origin xyz="0 0 0" rpy="0 0 0"/>
    </xacro:inertial_cylinder>

</link>

<joint name="right_wheel_joint" type="continuous">
    <parent link="base_link"/>
    <child link="right_wheel"/>
    <origin xyz="0 -0.175 0.0" rpy="${pi/2} 0 0"/>
    <axis xyz="0 0 -1"/>
</joint>

<!-- Caster Wheel Front-->
<link name="caster_wheel_f">
    <visual>
        <origin xyz="0 0 0" rpy="0 0 0"/>
        <geometry>
            <sphere radius="0.05" />
        </geometry>
        <material name="black"/>
    </visual>

    <collision>
         <origin xyz="0 0 0" rpy="0 0 0"/>
        <geometry>
            <sphere radius="0.05" />
        </geometry>
    </collision>

    <xacro:inertial_sphere mass="0.1" radius="0.05">
        <origin xyz="0 0 0" rpy="0 0 0"/>
    </xacro:inertial_sphere>
</link>

<joint name="caster_wheel_f_joint" type="fixed">
    <parent link="base_link"/>
    <child link="caster_wheel_f"/>
    <origin xyz="0.10 0 0" rpy="0 0 0"/>
</joint>

<!-- Caster Wheel Back-->
<link name="caster_wheel_b">
    <visual>
        <origin xyz="0 0 0" rpy="0 0 0"/>
        <geometry>
            <sphere radius="0.05" />
        </geometry>
        <material name="black"/>
    </visual>

    <collision>
         <origin xyz="0 0 0" rpy="0 0 0"/>
        <geometry>
            <sphere radius="0.05" />
        </geometry>
    </collision>

    <xacro:inertial_sphere mass="0.1" radius="0.05">
        <origin xyz="0 0 0" rpy="0 0 0"/>
    </xacro:inertial_sphere>
</link>

<joint name="caster_wheel_b_joint" type="fixed">
    <parent link="base_link"/>
    <child link="caster_wheel_b"/>
    <origin xyz="-0.10 0 0" rpy="0 0 0"/>
</joint>

</robot>